[main bbfbbda] Update
 3 files changed, 209 insertions(+), 2 deletions(-)
To https://github.com/iancharnas/clevelandlightning.git
   b72152b..bbfbbda  main -> main
[main fc87fc6] Update
 3 files changed, 13053 insertions(+)
To https://github.com/iancharnas/clevelandlightning.git
   bbfbbda..fc87fc6  main -> main
[main 9c55e7e] Update
 3 files changed, 49215 insertions(+), 1 deletion(-)
To https://github.com/iancharnas/clevelandlightning.git
   fc87fc6..9c55e7e  main -> main
[main 378e9cb] Update
 3 files changed, 73520 insertions(+)
 create mode 100644 data/2021-12-21.csv
To https://github.com/iancharnas/clevelandlightning.git
   9c55e7e..378e9cb  main -> main
[main 8e02f9d] Update
 3 files changed, 75356 insertions(+)
 create mode 100644 data/2021-12-22.csv
To https://github.com/iancharnas/clevelandlightning.git
   378e9cb..8e02f9d  main -> main
Traceback (most recent call last):
  File "scrapeBlitzortungLightningStrikes.py", line 67, in <module>
    # print(countries)
  File "scrapeBlitzortungLightningStrikes.py", line 26, in main
    [latitude, longitude, strike_time, server, mds, mcg, sta] = row
KeyboardInterrupt
Reading existing strikes...
Traceback (most recent call last):
  File "scrapeBlitzortungLightningStrikes.py", line 70, in <module>
    main()
  File "scrapeBlitzortungLightningStrikes.py", line 27, in main
    if strike_time not in recorded_times:
KeyboardInterrupt
Traceback (most recent call last):
  File "scrapeBlitzortungLightningStrikes.py", line 67, in <module>
    main()
  File "scrapeBlitzortungLightningStrikes.py", line 27, in main
    recorded_times.add(strike_time)
AttributeError: 'dict' object has no attribute 'add'
[main 805bd2c] Update
 5 files changed, 37330 insertions(+), 5 deletions(-)
 create mode 100644 data/2021-12-23.csv
To https://github.com/iancharnas/clevelandlightning.git
   8e02f9d..805bd2c  main -> main
[main 06f87a8] Update
 3 files changed, 28075 insertions(+)
 create mode 100644 data/2021-12-24.csv
To https://github.com/iancharnas/clevelandlightning.git
   805bd2c..06f87a8  main -> main
[main e0fa355] Update
 3 files changed, 17387 insertions(+)
 create mode 100644 data/2021-12-25.csv
To https://github.com/iancharnas/clevelandlightning.git
   06f87a8..e0fa355  main -> main
[main 7bbcaf6] Update
 3 files changed, 25234 insertions(+)
 create mode 100644 data/2021-12-26.csv
To https://github.com/iancharnas/clevelandlightning.git
   e0fa355..7bbcaf6  main -> main
[main 8c8fb2c] Update
 4 files changed, 30818 insertions(+), 1 deletion(-)
 rewrite clevelandstrikes.json (100%)
 create mode 100644 data/2021-12-27.csv
To https://github.com/iancharnas/clevelandlightning.git
   7bbcaf6..8c8fb2c  main -> main
[main ea88380] Update
 3 files changed, 28393 insertions(+)
 create mode 100644 data/2021-12-28.csv
To https://github.com/iancharnas/clevelandlightning.git
   8c8fb2c..ea88380  main -> main
[main 1b9479f] Update
 3 files changed, 44292 insertions(+)
 create mode 100644 data/2021-12-29.csv
To https://github.com/iancharnas/clevelandlightning.git
   ea88380..1b9479f  main -> main
[main 39e98ac] Update
 3 files changed, 142757 insertions(+)
 create mode 100644 data/2021-12-30.csv
To https://github.com/iancharnas/clevelandlightning.git
   1b9479f..39e98ac  main -> main
[main c4c71ab] Update
 3 files changed, 46925 insertions(+)
 create mode 100644 data/2021-12-31.csv
To https://github.com/iancharnas/clevelandlightning.git
   39e98ac..c4c71ab  main -> main
[main 221e15a] Update
 4 files changed, 71502 insertions(+), 1 deletion(-)
 create mode 100644 data/2022-01-01.csv
To https://github.com/iancharnas/clevelandlightning.git
   c4c71ab..221e15a  main -> main
Traceback (most recent call last):
  File "/home/pi/BlitzScraper/env/lib/python3.7/site-packages/urllib3/connection.py", line 175, in _new_conn
    (self._dns_host, self.port), self.timeout, **extra_kw
  File "/home/pi/BlitzScraper/env/lib/python3.7/site-packages/urllib3/util/connection.py", line 96, in create_connection
    raise err
  File "/home/pi/BlitzScraper/env/lib/python3.7/site-packages/urllib3/util/connection.py", line 86, in create_connection
    sock.connect(sa)
OSError: [Errno 101] Network is unreachable

During handling of the above exception, another exception occurred:

Traceback (most recent call last):
  File "/home/pi/BlitzScraper/env/lib/python3.7/site-packages/urllib3/connectionpool.py", line 706, in urlopen
    chunked=chunked,
  File "/home/pi/BlitzScraper/env/lib/python3.7/site-packages/urllib3/connectionpool.py", line 382, in _make_request
    self._validate_conn(conn)
  File "/home/pi/BlitzScraper/env/lib/python3.7/site-packages/urllib3/connectionpool.py", line 1010, in _validate_conn
    conn.connect()
  File "/home/pi/BlitzScraper/env/lib/python3.7/site-packages/urllib3/connection.py", line 358, in connect
    conn = self._new_conn()
  File "/home/pi/BlitzScraper/env/lib/python3.7/site-packages/urllib3/connection.py", line 187, in _new_conn
    self, "Failed to establish a new connection: %s" % e
urllib3.exceptions.NewConnectionError: <urllib3.connection.HTTPSConnection object at 0xb5b990d0>: Failed to establish a new connection: [Errno 101] Network is unreachable

During handling of the above exception, another exception occurred:

Traceback (most recent call last):
  File "/home/pi/BlitzScraper/env/lib/python3.7/site-packages/requests/adapters.py", line 449, in send
    timeout=timeout
  File "/home/pi/BlitzScraper/env/lib/python3.7/site-packages/urllib3/connectionpool.py", line 756, in urlopen
    method, url, error=e, _pool=self, _stacktrace=sys.exc_info()[2]
  File "/home/pi/BlitzScraper/env/lib/python3.7/site-packages/urllib3/util/retry.py", line 574, in increment
    raise MaxRetryError(_pool, url, error or ResponseError(cause))
urllib3.exceptions.MaxRetryError: HTTPSConnectionPool(host='map.blitzortung.org', port=443): Max retries exceeded with url: /GEOjson/getjson.php?f=s&n=00 (Caused by NewConnectionError('<urllib3.connection.HTTPSConnection object at 0xb5b990d0>: Failed to establish a new connection: [Errno 101] Network is unreachable'))

During handling of the above exception, another exception occurred:

Traceback (most recent call last):
  File "scrapeBlitzortungLightningStrikes.py", line 67, in <module>
    main()
  File "scrapeBlitzortungLightningStrikes.py", line 30, in main
    response = requests.get("https://map.blitzortung.org/GEOjson/getjson.php?f=s&n=00", headers={"Referer": "https://map.blitzortung.org/"})
  File "/home/pi/BlitzScraper/env/lib/python3.7/site-packages/requests/api.py", line 75, in get
    return request('get', url, params=params, **kwargs)
  File "/home/pi/BlitzScraper/env/lib/python3.7/site-packages/requests/api.py", line 61, in request
    return session.request(method=method, url=url, **kwargs)
  File "/home/pi/BlitzScraper/env/lib/python3.7/site-packages/requests/sessions.py", line 542, in request
    resp = self.send(prep, **send_kwargs)
  File "/home/pi/BlitzScraper/env/lib/python3.7/site-packages/requests/sessions.py", line 655, in send
    r = adapter.send(request, **kwargs)
  File "/home/pi/BlitzScraper/env/lib/python3.7/site-packages/requests/adapters.py", line 516, in send
    raise ConnectionError(e, request=request)
requests.exceptions.ConnectionError: HTTPSConnectionPool(host='map.blitzortung.org', port=443): Max retries exceeded with url: /GEOjson/getjson.php?f=s&n=00 (Caused by NewConnectionError('<urllib3.connection.HTTPSConnection object at 0xb5b990d0>: Failed to establish a new connection: [Errno 101] Network is unreachable'))
[main c8e461c] Update
 3 files changed, 66134 insertions(+)
 create mode 100644 data/2022-01-02.csv
To https://github.com/iancharnas/clevelandlightning.git
   221e15a..c8e461c  main -> main
