[main bbfbbda] Update
 3 files changed, 209 insertions(+), 2 deletions(-)
To https://github.com/iancharnas/clevelandlightning.git
   b72152b..bbfbbda  main -> main
[main fc87fc6] Update
 3 files changed, 13053 insertions(+)
To https://github.com/iancharnas/clevelandlightning.git
   bbfbbda..fc87fc6  main -> main
[main 9c55e7e] Update
 3 files changed, 49215 insertions(+), 1 deletion(-)
To https://github.com/iancharnas/clevelandlightning.git
   fc87fc6..9c55e7e  main -> main
[main 378e9cb] Update
 3 files changed, 73520 insertions(+)
 create mode 100644 data/2021-12-21.csv
To https://github.com/iancharnas/clevelandlightning.git
   9c55e7e..378e9cb  main -> main
[main 8e02f9d] Update
 3 files changed, 75356 insertions(+)
 create mode 100644 data/2021-12-22.csv
To https://github.com/iancharnas/clevelandlightning.git
   378e9cb..8e02f9d  main -> main
Traceback (most recent call last):
  File "scrapeBlitzortungLightningStrikes.py", line 67, in <module>
    # print(countries)
  File "scrapeBlitzortungLightningStrikes.py", line 26, in main
    [latitude, longitude, strike_time, server, mds, mcg, sta] = row
KeyboardInterrupt
Reading existing strikes...
Traceback (most recent call last):
  File "scrapeBlitzortungLightningStrikes.py", line 70, in <module>
    main()
  File "scrapeBlitzortungLightningStrikes.py", line 27, in main
    if strike_time not in recorded_times:
KeyboardInterrupt
Traceback (most recent call last):
  File "scrapeBlitzortungLightningStrikes.py", line 67, in <module>
    main()
  File "scrapeBlitzortungLightningStrikes.py", line 27, in main
    recorded_times.add(strike_time)
AttributeError: 'dict' object has no attribute 'add'
[main 805bd2c] Update
 5 files changed, 37330 insertions(+), 5 deletions(-)
 create mode 100644 data/2021-12-23.csv
To https://github.com/iancharnas/clevelandlightning.git
   8e02f9d..805bd2c  main -> main
[main 06f87a8] Update
 3 files changed, 28075 insertions(+)
 create mode 100644 data/2021-12-24.csv
To https://github.com/iancharnas/clevelandlightning.git
   805bd2c..06f87a8  main -> main
[main e0fa355] Update
 3 files changed, 17387 insertions(+)
 create mode 100644 data/2021-12-25.csv
To https://github.com/iancharnas/clevelandlightning.git
   06f87a8..e0fa355  main -> main
[main 7bbcaf6] Update
 3 files changed, 25234 insertions(+)
 create mode 100644 data/2021-12-26.csv
To https://github.com/iancharnas/clevelandlightning.git
   e0fa355..7bbcaf6  main -> main
[main 8c8fb2c] Update
 4 files changed, 30818 insertions(+), 1 deletion(-)
 rewrite clevelandstrikes.json (100%)
 create mode 100644 data/2021-12-27.csv
To https://github.com/iancharnas/clevelandlightning.git
   7bbcaf6..8c8fb2c  main -> main
[main ea88380] Update
 3 files changed, 28393 insertions(+)
 create mode 100644 data/2021-12-28.csv
To https://github.com/iancharnas/clevelandlightning.git
   8c8fb2c..ea88380  main -> main
[main 1b9479f] Update
 3 files changed, 44292 insertions(+)
 create mode 100644 data/2021-12-29.csv
To https://github.com/iancharnas/clevelandlightning.git
   ea88380..1b9479f  main -> main
[main 39e98ac] Update
 3 files changed, 142757 insertions(+)
 create mode 100644 data/2021-12-30.csv
To https://github.com/iancharnas/clevelandlightning.git
   1b9479f..39e98ac  main -> main
[main c4c71ab] Update
 3 files changed, 46925 insertions(+)
 create mode 100644 data/2021-12-31.csv
To https://github.com/iancharnas/clevelandlightning.git
   39e98ac..c4c71ab  main -> main
[main 221e15a] Update
 4 files changed, 71502 insertions(+), 1 deletion(-)
 create mode 100644 data/2022-01-01.csv
To https://github.com/iancharnas/clevelandlightning.git
   c4c71ab..221e15a  main -> main
Traceback (most recent call last):
  File "/home/pi/BlitzScraper/env/lib/python3.7/site-packages/urllib3/connection.py", line 175, in _new_conn
    (self._dns_host, self.port), self.timeout, **extra_kw
  File "/home/pi/BlitzScraper/env/lib/python3.7/site-packages/urllib3/util/connection.py", line 96, in create_connection
    raise err
  File "/home/pi/BlitzScraper/env/lib/python3.7/site-packages/urllib3/util/connection.py", line 86, in create_connection
    sock.connect(sa)
OSError: [Errno 101] Network is unreachable

During handling of the above exception, another exception occurred:

Traceback (most recent call last):
  File "/home/pi/BlitzScraper/env/lib/python3.7/site-packages/urllib3/connectionpool.py", line 706, in urlopen
    chunked=chunked,
  File "/home/pi/BlitzScraper/env/lib/python3.7/site-packages/urllib3/connectionpool.py", line 382, in _make_request
    self._validate_conn(conn)
  File "/home/pi/BlitzScraper/env/lib/python3.7/site-packages/urllib3/connectionpool.py", line 1010, in _validate_conn
    conn.connect()
  File "/home/pi/BlitzScraper/env/lib/python3.7/site-packages/urllib3/connection.py", line 358, in connect
    conn = self._new_conn()
  File "/home/pi/BlitzScraper/env/lib/python3.7/site-packages/urllib3/connection.py", line 187, in _new_conn
    self, "Failed to establish a new connection: %s" % e
urllib3.exceptions.NewConnectionError: <urllib3.connection.HTTPSConnection object at 0xb5b990d0>: Failed to establish a new connection: [Errno 101] Network is unreachable

During handling of the above exception, another exception occurred:

Traceback (most recent call last):
  File "/home/pi/BlitzScraper/env/lib/python3.7/site-packages/requests/adapters.py", line 449, in send
    timeout=timeout
  File "/home/pi/BlitzScraper/env/lib/python3.7/site-packages/urllib3/connectionpool.py", line 756, in urlopen
    method, url, error=e, _pool=self, _stacktrace=sys.exc_info()[2]
  File "/home/pi/BlitzScraper/env/lib/python3.7/site-packages/urllib3/util/retry.py", line 574, in increment
    raise MaxRetryError(_pool, url, error or ResponseError(cause))
urllib3.exceptions.MaxRetryError: HTTPSConnectionPool(host='map.blitzortung.org', port=443): Max retries exceeded with url: /GEOjson/getjson.php?f=s&n=00 (Caused by NewConnectionError('<urllib3.connection.HTTPSConnection object at 0xb5b990d0>: Failed to establish a new connection: [Errno 101] Network is unreachable'))

During handling of the above exception, another exception occurred:

Traceback (most recent call last):
  File "scrapeBlitzortungLightningStrikes.py", line 67, in <module>
    main()
  File "scrapeBlitzortungLightningStrikes.py", line 30, in main
    response = requests.get("https://map.blitzortung.org/GEOjson/getjson.php?f=s&n=00", headers={"Referer": "https://map.blitzortung.org/"})
  File "/home/pi/BlitzScraper/env/lib/python3.7/site-packages/requests/api.py", line 75, in get
    return request('get', url, params=params, **kwargs)
  File "/home/pi/BlitzScraper/env/lib/python3.7/site-packages/requests/api.py", line 61, in request
    return session.request(method=method, url=url, **kwargs)
  File "/home/pi/BlitzScraper/env/lib/python3.7/site-packages/requests/sessions.py", line 542, in request
    resp = self.send(prep, **send_kwargs)
  File "/home/pi/BlitzScraper/env/lib/python3.7/site-packages/requests/sessions.py", line 655, in send
    r = adapter.send(request, **kwargs)
  File "/home/pi/BlitzScraper/env/lib/python3.7/site-packages/requests/adapters.py", line 516, in send
    raise ConnectionError(e, request=request)
requests.exceptions.ConnectionError: HTTPSConnectionPool(host='map.blitzortung.org', port=443): Max retries exceeded with url: /GEOjson/getjson.php?f=s&n=00 (Caused by NewConnectionError('<urllib3.connection.HTTPSConnection object at 0xb5b990d0>: Failed to establish a new connection: [Errno 101] Network is unreachable'))
[main c8e461c] Update
 3 files changed, 66134 insertions(+)
 create mode 100644 data/2022-01-02.csv
To https://github.com/iancharnas/clevelandlightning.git
   221e15a..c8e461c  main -> main
[main 64e23c7] Update
 3 files changed, 53222 insertions(+)
 create mode 100644 data/2022-01-03.csv
To https://github.com/iancharnas/clevelandlightning.git
   c8e461c..64e23c7  main -> main
[main 486b1de] Update
 3 files changed, 16715 insertions(+)
 create mode 100644 data/2022-01-04.csv
To https://github.com/iancharnas/clevelandlightning.git
   64e23c7..486b1de  main -> main
Traceback (most recent call last):
  File "/home/pi/BlitzScraper/env/lib/python3.7/site-packages/urllib3/connection.py", line 175, in _new_conn
    (self._dns_host, self.port), self.timeout, **extra_kw
  File "/home/pi/BlitzScraper/env/lib/python3.7/site-packages/urllib3/util/connection.py", line 96, in create_connection
    raise err
  File "/home/pi/BlitzScraper/env/lib/python3.7/site-packages/urllib3/util/connection.py", line 86, in create_connection
    sock.connect(sa)
OSError: [Errno 101] Network is unreachable

During handling of the above exception, another exception occurred:

Traceback (most recent call last):
  File "/home/pi/BlitzScraper/env/lib/python3.7/site-packages/urllib3/connectionpool.py", line 706, in urlopen
    chunked=chunked,
  File "/home/pi/BlitzScraper/env/lib/python3.7/site-packages/urllib3/connectionpool.py", line 382, in _make_request
    self._validate_conn(conn)
  File "/home/pi/BlitzScraper/env/lib/python3.7/site-packages/urllib3/connectionpool.py", line 1010, in _validate_conn
    conn.connect()
  File "/home/pi/BlitzScraper/env/lib/python3.7/site-packages/urllib3/connection.py", line 358, in connect
    conn = self._new_conn()
  File "/home/pi/BlitzScraper/env/lib/python3.7/site-packages/urllib3/connection.py", line 187, in _new_conn
    self, "Failed to establish a new connection: %s" % e
urllib3.exceptions.NewConnectionError: <urllib3.connection.HTTPSConnection object at 0xb5bb7170>: Failed to establish a new connection: [Errno 101] Network is unreachable

During handling of the above exception, another exception occurred:

Traceback (most recent call last):
  File "/home/pi/BlitzScraper/env/lib/python3.7/site-packages/requests/adapters.py", line 449, in send
    timeout=timeout
  File "/home/pi/BlitzScraper/env/lib/python3.7/site-packages/urllib3/connectionpool.py", line 756, in urlopen
    method, url, error=e, _pool=self, _stacktrace=sys.exc_info()[2]
  File "/home/pi/BlitzScraper/env/lib/python3.7/site-packages/urllib3/util/retry.py", line 574, in increment
    raise MaxRetryError(_pool, url, error or ResponseError(cause))
urllib3.exceptions.MaxRetryError: HTTPSConnectionPool(host='map.blitzortung.org', port=443): Max retries exceeded with url: /GEOjson/getjson.php?f=s&n=00 (Caused by NewConnectionError('<urllib3.connection.HTTPSConnection object at 0xb5bb7170>: Failed to establish a new connection: [Errno 101] Network is unreachable'))

During handling of the above exception, another exception occurred:

Traceback (most recent call last):
  File "scrapeBlitzortungLightningStrikes.py", line 67, in <module>
    main()
  File "scrapeBlitzortungLightningStrikes.py", line 30, in main
    response = requests.get("https://map.blitzortung.org/GEOjson/getjson.php?f=s&n=00", headers={"Referer": "https://map.blitzortung.org/"})
  File "/home/pi/BlitzScraper/env/lib/python3.7/site-packages/requests/api.py", line 75, in get
    return request('get', url, params=params, **kwargs)
  File "/home/pi/BlitzScraper/env/lib/python3.7/site-packages/requests/api.py", line 61, in request
    return session.request(method=method, url=url, **kwargs)
  File "/home/pi/BlitzScraper/env/lib/python3.7/site-packages/requests/sessions.py", line 542, in request
    resp = self.send(prep, **send_kwargs)
  File "/home/pi/BlitzScraper/env/lib/python3.7/site-packages/requests/sessions.py", line 655, in send
    r = adapter.send(request, **kwargs)
  File "/home/pi/BlitzScraper/env/lib/python3.7/site-packages/requests/adapters.py", line 516, in send
    raise ConnectionError(e, request=request)
requests.exceptions.ConnectionError: HTTPSConnectionPool(host='map.blitzortung.org', port=443): Max retries exceeded with url: /GEOjson/getjson.php?f=s&n=00 (Caused by NewConnectionError('<urllib3.connection.HTTPSConnection object at 0xb5bb7170>: Failed to establish a new connection: [Errno 101] Network is unreachable'))
Traceback (most recent call last):
  File "/home/pi/BlitzScraper/env/lib/python3.7/site-packages/urllib3/connection.py", line 175, in _new_conn
    (self._dns_host, self.port), self.timeout, **extra_kw
  File "/home/pi/BlitzScraper/env/lib/python3.7/site-packages/urllib3/util/connection.py", line 96, in create_connection
    raise err
  File "/home/pi/BlitzScraper/env/lib/python3.7/site-packages/urllib3/util/connection.py", line 86, in create_connection
    sock.connect(sa)
OSError: [Errno 101] Network is unreachable

During handling of the above exception, another exception occurred:

Traceback (most recent call last):
  File "/home/pi/BlitzScraper/env/lib/python3.7/site-packages/urllib3/connectionpool.py", line 706, in urlopen
    chunked=chunked,
  File "/home/pi/BlitzScraper/env/lib/python3.7/site-packages/urllib3/connectionpool.py", line 382, in _make_request
    self._validate_conn(conn)
  File "/home/pi/BlitzScraper/env/lib/python3.7/site-packages/urllib3/connectionpool.py", line 1010, in _validate_conn
    conn.connect()
  File "/home/pi/BlitzScraper/env/lib/python3.7/site-packages/urllib3/connection.py", line 358, in connect
    conn = self._new_conn()
  File "/home/pi/BlitzScraper/env/lib/python3.7/site-packages/urllib3/connection.py", line 187, in _new_conn
    self, "Failed to establish a new connection: %s" % e
urllib3.exceptions.NewConnectionError: <urllib3.connection.HTTPSConnection object at 0xb5ba9090>: Failed to establish a new connection: [Errno 101] Network is unreachable

During handling of the above exception, another exception occurred:

Traceback (most recent call last):
  File "/home/pi/BlitzScraper/env/lib/python3.7/site-packages/requests/adapters.py", line 449, in send
    timeout=timeout
  File "/home/pi/BlitzScraper/env/lib/python3.7/site-packages/urllib3/connectionpool.py", line 756, in urlopen
    method, url, error=e, _pool=self, _stacktrace=sys.exc_info()[2]
  File "/home/pi/BlitzScraper/env/lib/python3.7/site-packages/urllib3/util/retry.py", line 574, in increment
    raise MaxRetryError(_pool, url, error or ResponseError(cause))
urllib3.exceptions.MaxRetryError: HTTPSConnectionPool(host='map.blitzortung.org', port=443): Max retries exceeded with url: /GEOjson/getjson.php?f=s&n=00 (Caused by NewConnectionError('<urllib3.connection.HTTPSConnection object at 0xb5ba9090>: Failed to establish a new connection: [Errno 101] Network is unreachable'))

During handling of the above exception, another exception occurred:

Traceback (most recent call last):
  File "scrapeBlitzortungLightningStrikes.py", line 67, in <module>
    main()
  File "scrapeBlitzortungLightningStrikes.py", line 30, in main
    response = requests.get("https://map.blitzortung.org/GEOjson/getjson.php?f=s&n=00", headers={"Referer": "https://map.blitzortung.org/"})
  File "/home/pi/BlitzScraper/env/lib/python3.7/site-packages/requests/api.py", line 75, in get
    return request('get', url, params=params, **kwargs)
  File "/home/pi/BlitzScraper/env/lib/python3.7/site-packages/requests/api.py", line 61, in request
    return session.request(method=method, url=url, **kwargs)
  File "/home/pi/BlitzScraper/env/lib/python3.7/site-packages/requests/sessions.py", line 542, in request
    resp = self.send(prep, **send_kwargs)
  File "/home/pi/BlitzScraper/env/lib/python3.7/site-packages/requests/sessions.py", line 655, in send
    r = adapter.send(request, **kwargs)
  File "/home/pi/BlitzScraper/env/lib/python3.7/site-packages/requests/adapters.py", line 516, in send
    raise ConnectionError(e, request=request)
requests.exceptions.ConnectionError: HTTPSConnectionPool(host='map.blitzortung.org', port=443): Max retries exceeded with url: /GEOjson/getjson.php?f=s&n=00 (Caused by NewConnectionError('<urllib3.connection.HTTPSConnection object at 0xb5ba9090>: Failed to establish a new connection: [Errno 101] Network is unreachable'))
Traceback (most recent call last):
  File "/home/pi/BlitzScraper/env/lib/python3.7/site-packages/urllib3/connection.py", line 175, in _new_conn
    (self._dns_host, self.port), self.timeout, **extra_kw
  File "/home/pi/BlitzScraper/env/lib/python3.7/site-packages/urllib3/util/connection.py", line 96, in create_connection
    raise err
  File "/home/pi/BlitzScraper/env/lib/python3.7/site-packages/urllib3/util/connection.py", line 86, in create_connection
    sock.connect(sa)
OSError: [Errno 101] Network is unreachable

During handling of the above exception, another exception occurred:

Traceback (most recent call last):
  File "/home/pi/BlitzScraper/env/lib/python3.7/site-packages/urllib3/connectionpool.py", line 706, in urlopen
    chunked=chunked,
  File "/home/pi/BlitzScraper/env/lib/python3.7/site-packages/urllib3/connectionpool.py", line 382, in _make_request
    self._validate_conn(conn)
  File "/home/pi/BlitzScraper/env/lib/python3.7/site-packages/urllib3/connectionpool.py", line 1010, in _validate_conn
    conn.connect()
  File "/home/pi/BlitzScraper/env/lib/python3.7/site-packages/urllib3/connection.py", line 358, in connect
    conn = self._new_conn()
  File "/home/pi/BlitzScraper/env/lib/python3.7/site-packages/urllib3/connection.py", line 187, in _new_conn
    self, "Failed to establish a new connection: %s" % e
urllib3.exceptions.NewConnectionError: <urllib3.connection.HTTPSConnection object at 0xb5bde130>: Failed to establish a new connection: [Errno 101] Network is unreachable

During handling of the above exception, another exception occurred:

Traceback (most recent call last):
  File "/home/pi/BlitzScraper/env/lib/python3.7/site-packages/requests/adapters.py", line 449, in send
    timeout=timeout
  File "/home/pi/BlitzScraper/env/lib/python3.7/site-packages/urllib3/connectionpool.py", line 756, in urlopen
    method, url, error=e, _pool=self, _stacktrace=sys.exc_info()[2]
  File "/home/pi/BlitzScraper/env/lib/python3.7/site-packages/urllib3/util/retry.py", line 574, in increment
    raise MaxRetryError(_pool, url, error or ResponseError(cause))
urllib3.exceptions.MaxRetryError: HTTPSConnectionPool(host='map.blitzortung.org', port=443): Max retries exceeded with url: /GEOjson/getjson.php?f=s&n=00 (Caused by NewConnectionError('<urllib3.connection.HTTPSConnection object at 0xb5bde130>: Failed to establish a new connection: [Errno 101] Network is unreachable'))

During handling of the above exception, another exception occurred:

Traceback (most recent call last):
  File "scrapeBlitzortungLightningStrikes.py", line 67, in <module>
    main()
  File "scrapeBlitzortungLightningStrikes.py", line 30, in main
    response = requests.get("https://map.blitzortung.org/GEOjson/getjson.php?f=s&n=00", headers={"Referer": "https://map.blitzortung.org/"})
  File "/home/pi/BlitzScraper/env/lib/python3.7/site-packages/requests/api.py", line 75, in get
    return request('get', url, params=params, **kwargs)
  File "/home/pi/BlitzScraper/env/lib/python3.7/site-packages/requests/api.py", line 61, in request
    return session.request(method=method, url=url, **kwargs)
  File "/home/pi/BlitzScraper/env/lib/python3.7/site-packages/requests/sessions.py", line 542, in request
    resp = self.send(prep, **send_kwargs)
  File "/home/pi/BlitzScraper/env/lib/python3.7/site-packages/requests/sessions.py", line 655, in send
    r = adapter.send(request, **kwargs)
  File "/home/pi/BlitzScraper/env/lib/python3.7/site-packages/requests/adapters.py", line 516, in send
    raise ConnectionError(e, request=request)
requests.exceptions.ConnectionError: HTTPSConnectionPool(host='map.blitzortung.org', port=443): Max retries exceeded with url: /GEOjson/getjson.php?f=s&n=00 (Caused by NewConnectionError('<urllib3.connection.HTTPSConnection object at 0xb5bde130>: Failed to establish a new connection: [Errno 101] Network is unreachable'))
Traceback (most recent call last):
  File "/home/pi/BlitzScraper/env/lib/python3.7/site-packages/urllib3/connection.py", line 175, in _new_conn
    (self._dns_host, self.port), self.timeout, **extra_kw
  File "/home/pi/BlitzScraper/env/lib/python3.7/site-packages/urllib3/util/connection.py", line 96, in create_connection
    raise err
  File "/home/pi/BlitzScraper/env/lib/python3.7/site-packages/urllib3/util/connection.py", line 86, in create_connection
    sock.connect(sa)
OSError: [Errno 101] Network is unreachable

During handling of the above exception, another exception occurred:

Traceback (most recent call last):
  File "/home/pi/BlitzScraper/env/lib/python3.7/site-packages/urllib3/connectionpool.py", line 706, in urlopen
    chunked=chunked,
  File "/home/pi/BlitzScraper/env/lib/python3.7/site-packages/urllib3/connectionpool.py", line 382, in _make_request
    self._validate_conn(conn)
  File "/home/pi/BlitzScraper/env/lib/python3.7/site-packages/urllib3/connectionpool.py", line 1010, in _validate_conn
    conn.connect()
  File "/home/pi/BlitzScraper/env/lib/python3.7/site-packages/urllib3/connection.py", line 358, in connect
    conn = self._new_conn()
  File "/home/pi/BlitzScraper/env/lib/python3.7/site-packages/urllib3/connection.py", line 187, in _new_conn
    self, "Failed to establish a new connection: %s" % e
urllib3.exceptions.NewConnectionError: <urllib3.connection.HTTPSConnection object at 0xb5c690b0>: Failed to establish a new connection: [Errno 101] Network is unreachable

During handling of the above exception, another exception occurred:

Traceback (most recent call last):
  File "/home/pi/BlitzScraper/env/lib/python3.7/site-packages/requests/adapters.py", line 449, in send
    timeout=timeout
  File "/home/pi/BlitzScraper/env/lib/python3.7/site-packages/urllib3/connectionpool.py", line 756, in urlopen
    method, url, error=e, _pool=self, _stacktrace=sys.exc_info()[2]
  File "/home/pi/BlitzScraper/env/lib/python3.7/site-packages/urllib3/util/retry.py", line 574, in increment
    raise MaxRetryError(_pool, url, error or ResponseError(cause))
urllib3.exceptions.MaxRetryError: HTTPSConnectionPool(host='map.blitzortung.org', port=443): Max retries exceeded with url: /GEOjson/getjson.php?f=s&n=00 (Caused by NewConnectionError('<urllib3.connection.HTTPSConnection object at 0xb5c690b0>: Failed to establish a new connection: [Errno 101] Network is unreachable'))

During handling of the above exception, another exception occurred:

Traceback (most recent call last):
  File "scrapeBlitzortungLightningStrikes.py", line 67, in <module>
    main()
  File "scrapeBlitzortungLightningStrikes.py", line 30, in main
    response = requests.get("https://map.blitzortung.org/GEOjson/getjson.php?f=s&n=00", headers={"Referer": "https://map.blitzortung.org/"})
  File "/home/pi/BlitzScraper/env/lib/python3.7/site-packages/requests/api.py", line 75, in get
    return request('get', url, params=params, **kwargs)
  File "/home/pi/BlitzScraper/env/lib/python3.7/site-packages/requests/api.py", line 61, in request
    return session.request(method=method, url=url, **kwargs)
  File "/home/pi/BlitzScraper/env/lib/python3.7/site-packages/requests/sessions.py", line 542, in request
    resp = self.send(prep, **send_kwargs)
  File "/home/pi/BlitzScraper/env/lib/python3.7/site-packages/requests/sessions.py", line 655, in send
    r = adapter.send(request, **kwargs)
  File "/home/pi/BlitzScraper/env/lib/python3.7/site-packages/requests/adapters.py", line 516, in send
    raise ConnectionError(e, request=request)
requests.exceptions.ConnectionError: HTTPSConnectionPool(host='map.blitzortung.org', port=443): Max retries exceeded with url: /GEOjson/getjson.php?f=s&n=00 (Caused by NewConnectionError('<urllib3.connection.HTTPSConnection object at 0xb5c690b0>: Failed to establish a new connection: [Errno 101] Network is unreachable'))
[main 14afe7d] Update
 3 files changed, 60434 insertions(+)
 create mode 100644 data/2022-01-05.csv
To https://github.com/iancharnas/clevelandlightning.git
   486b1de..14afe7d  main -> main
[main 5021d4b] Update
 3 files changed, 46351 insertions(+)
 create mode 100644 data/2022-01-06.csv
To https://github.com/iancharnas/clevelandlightning.git
   14afe7d..5021d4b  main -> main
[main 00fcc57] Update
 3 files changed, 102626 insertions(+)
 create mode 100644 data/2022-01-07.csv
To https://github.com/iancharnas/clevelandlightning.git
   5021d4b..00fcc57  main -> main
[main 15121b4] Update
 3 files changed, 133097 insertions(+)
 create mode 100644 data/2022-01-08.csv
To https://github.com/iancharnas/clevelandlightning.git
   00fcc57..15121b4  main -> main
[main f5f2bde] Update
 3 files changed, 192759 insertions(+)
 create mode 100644 data/2022-01-09.csv
To https://github.com/iancharnas/clevelandlightning.git
   15121b4..f5f2bde  main -> main
[main c64ba18] Update
 4 files changed, 203820 insertions(+), 1 deletion(-)
 create mode 100644 data/2022-01-10.csv
To https://github.com/iancharnas/clevelandlightning.git
   f5f2bde..c64ba18  main -> main
[main 7379afe] Update
 3 files changed, 48280 insertions(+)
 create mode 100644 data/2022-01-11.csv
To https://github.com/iancharnas/clevelandlightning.git
   c64ba18..7379afe  main -> main
[main 4ba9274] Update
 3 files changed, 36335 insertions(+)
 create mode 100644 data/2022-01-12.csv
To https://github.com/iancharnas/clevelandlightning.git
   7379afe..4ba9274  main -> main
[main de72278] Update
 3 files changed, 46890 insertions(+)
 create mode 100644 data/2022-01-13.csv
To https://github.com/iancharnas/clevelandlightning.git
   4ba9274..de72278  main -> main
[main 6acd47b] Update
 3 files changed, 72278 insertions(+)
 create mode 100644 data/2022-01-14.csv
To https://github.com/iancharnas/clevelandlightning.git
   de72278..6acd47b  main -> main
[main eeb439d] Update
 3 files changed, 52795 insertions(+)
 create mode 100644 data/2022-01-15.csv
To https://github.com/iancharnas/clevelandlightning.git
   6acd47b..eeb439d  main -> main
[main f6033fa] Update
 3 files changed, 73977 insertions(+)
 create mode 100644 data/2022-01-16.csv
To https://github.com/iancharnas/clevelandlightning.git
   eeb439d..f6033fa  main -> main
[main b88909a] Update
 3 files changed, 79382 insertions(+)
 create mode 100644 data/2022-01-17.csv
To https://github.com/iancharnas/clevelandlightning.git
   f6033fa..b88909a  main -> main
[main 7e607a9] Update
 3 files changed, 33259 insertions(+)
 create mode 100644 data/2022-01-18.csv
To https://github.com/iancharnas/clevelandlightning.git
   b88909a..7e607a9  main -> main
[main f6c0078] Update
 3 files changed, 31467 insertions(+)
 create mode 100644 data/2022-01-19.csv
To https://github.com/iancharnas/clevelandlightning.git
   7e607a9..f6c0078  main -> main
[main 004296c] Update
 3 files changed, 39668 insertions(+)
 create mode 100644 data/2022-01-20.csv
To https://github.com/iancharnas/clevelandlightning.git
   f6c0078..004296c  main -> main
[main 02f5d93] Update
 3 files changed, 26132 insertions(+)
 create mode 100644 data/2022-01-21.csv
To https://github.com/iancharnas/clevelandlightning.git
   004296c..02f5d93  main -> main
[main 17f9e4f] Update
 3 files changed, 49726 insertions(+)
 create mode 100644 data/2022-01-22.csv
To https://github.com/iancharnas/clevelandlightning.git
   02f5d93..17f9e4f  main -> main
[main 8953d6e] Update
 3 files changed, 26350 insertions(+)
 create mode 100644 data/2022-01-23.csv
To https://github.com/iancharnas/clevelandlightning.git
   17f9e4f..8953d6e  main -> main
[main 5cad86b] Update
 3 files changed, 23000 insertions(+)
 create mode 100644 data/2022-01-24.csv
To https://github.com/iancharnas/clevelandlightning.git
   8953d6e..5cad86b  main -> main
[main 5550ae5] Update
 3 files changed, 46030 insertions(+)
 create mode 100644 data/2022-01-25.csv
To https://github.com/iancharnas/clevelandlightning.git
   5cad86b..5550ae5  main -> main
Traceback (most recent call last):
  File "/home/pi/BlitzScraper/env/lib/python3.7/site-packages/urllib3/connection.py", line 175, in _new_conn
    (self._dns_host, self.port), self.timeout, **extra_kw
  File "/home/pi/BlitzScraper/env/lib/python3.7/site-packages/urllib3/util/connection.py", line 96, in create_connection
    raise err
  File "/home/pi/BlitzScraper/env/lib/python3.7/site-packages/urllib3/util/connection.py", line 86, in create_connection
    sock.connect(sa)
OSError: [Errno 101] Network is unreachable

During handling of the above exception, another exception occurred:

Traceback (most recent call last):
  File "/home/pi/BlitzScraper/env/lib/python3.7/site-packages/urllib3/connectionpool.py", line 706, in urlopen
    chunked=chunked,
  File "/home/pi/BlitzScraper/env/lib/python3.7/site-packages/urllib3/connectionpool.py", line 382, in _make_request
    self._validate_conn(conn)
  File "/home/pi/BlitzScraper/env/lib/python3.7/site-packages/urllib3/connectionpool.py", line 1010, in _validate_conn
    conn.connect()
  File "/home/pi/BlitzScraper/env/lib/python3.7/site-packages/urllib3/connection.py", line 358, in connect
    conn = self._new_conn()
  File "/home/pi/BlitzScraper/env/lib/python3.7/site-packages/urllib3/connection.py", line 187, in _new_conn
    self, "Failed to establish a new connection: %s" % e
urllib3.exceptions.NewConnectionError: <urllib3.connection.HTTPSConnection object at 0xb5ef20d0>: Failed to establish a new connection: [Errno 101] Network is unreachable

During handling of the above exception, another exception occurred:

Traceback (most recent call last):
  File "/home/pi/BlitzScraper/env/lib/python3.7/site-packages/requests/adapters.py", line 449, in send
    timeout=timeout
  File "/home/pi/BlitzScraper/env/lib/python3.7/site-packages/urllib3/connectionpool.py", line 756, in urlopen
    method, url, error=e, _pool=self, _stacktrace=sys.exc_info()[2]
  File "/home/pi/BlitzScraper/env/lib/python3.7/site-packages/urllib3/util/retry.py", line 574, in increment
    raise MaxRetryError(_pool, url, error or ResponseError(cause))
urllib3.exceptions.MaxRetryError: HTTPSConnectionPool(host='map.blitzortung.org', port=443): Max retries exceeded with url: /GEOjson/getjson.php?f=s&n=00 (Caused by NewConnectionError('<urllib3.connection.HTTPSConnection object at 0xb5ef20d0>: Failed to establish a new connection: [Errno 101] Network is unreachable'))

During handling of the above exception, another exception occurred:

Traceback (most recent call last):
  File "scrapeBlitzortungLightningStrikes.py", line 67, in <module>
    main()
  File "scrapeBlitzortungLightningStrikes.py", line 30, in main
    response = requests.get("https://map.blitzortung.org/GEOjson/getjson.php?f=s&n=00", headers={"Referer": "https://map.blitzortung.org/"})
  File "/home/pi/BlitzScraper/env/lib/python3.7/site-packages/requests/api.py", line 75, in get
    return request('get', url, params=params, **kwargs)
  File "/home/pi/BlitzScraper/env/lib/python3.7/site-packages/requests/api.py", line 61, in request
    return session.request(method=method, url=url, **kwargs)
  File "/home/pi/BlitzScraper/env/lib/python3.7/site-packages/requests/sessions.py", line 542, in request
    resp = self.send(prep, **send_kwargs)
  File "/home/pi/BlitzScraper/env/lib/python3.7/site-packages/requests/sessions.py", line 655, in send
    r = adapter.send(request, **kwargs)
  File "/home/pi/BlitzScraper/env/lib/python3.7/site-packages/requests/adapters.py", line 516, in send
    raise ConnectionError(e, request=request)
requests.exceptions.ConnectionError: HTTPSConnectionPool(host='map.blitzortung.org', port=443): Max retries exceeded with url: /GEOjson/getjson.php?f=s&n=00 (Caused by NewConnectionError('<urllib3.connection.HTTPSConnection object at 0xb5ef20d0>: Failed to establish a new connection: [Errno 101] Network is unreachable'))
Traceback (most recent call last):
  File "/home/pi/BlitzScraper/env/lib/python3.7/site-packages/urllib3/connection.py", line 175, in _new_conn
    (self._dns_host, self.port), self.timeout, **extra_kw
  File "/home/pi/BlitzScraper/env/lib/python3.7/site-packages/urllib3/util/connection.py", line 96, in create_connection
    raise err
  File "/home/pi/BlitzScraper/env/lib/python3.7/site-packages/urllib3/util/connection.py", line 86, in create_connection
    sock.connect(sa)
OSError: [Errno 101] Network is unreachable

During handling of the above exception, another exception occurred:

Traceback (most recent call last):
  File "/home/pi/BlitzScraper/env/lib/python3.7/site-packages/urllib3/connectionpool.py", line 706, in urlopen
    chunked=chunked,
  File "/home/pi/BlitzScraper/env/lib/python3.7/site-packages/urllib3/connectionpool.py", line 382, in _make_request
    self._validate_conn(conn)
  File "/home/pi/BlitzScraper/env/lib/python3.7/site-packages/urllib3/connectionpool.py", line 1010, in _validate_conn
    conn.connect()
  File "/home/pi/BlitzScraper/env/lib/python3.7/site-packages/urllib3/connection.py", line 358, in connect
    conn = self._new_conn()
  File "/home/pi/BlitzScraper/env/lib/python3.7/site-packages/urllib3/connection.py", line 187, in _new_conn
    self, "Failed to establish a new connection: %s" % e
urllib3.exceptions.NewConnectionError: <urllib3.connection.HTTPSConnection object at 0xb5e5f050>: Failed to establish a new connection: [Errno 101] Network is unreachable

During handling of the above exception, another exception occurred:

Traceback (most recent call last):
  File "/home/pi/BlitzScraper/env/lib/python3.7/site-packages/requests/adapters.py", line 449, in send
    timeout=timeout
  File "/home/pi/BlitzScraper/env/lib/python3.7/site-packages/urllib3/connectionpool.py", line 756, in urlopen
    method, url, error=e, _pool=self, _stacktrace=sys.exc_info()[2]
  File "/home/pi/BlitzScraper/env/lib/python3.7/site-packages/urllib3/util/retry.py", line 574, in increment
    raise MaxRetryError(_pool, url, error or ResponseError(cause))
urllib3.exceptions.MaxRetryError: HTTPSConnectionPool(host='map.blitzortung.org', port=443): Max retries exceeded with url: /GEOjson/getjson.php?f=s&n=00 (Caused by NewConnectionError('<urllib3.connection.HTTPSConnection object at 0xb5e5f050>: Failed to establish a new connection: [Errno 101] Network is unreachable'))

During handling of the above exception, another exception occurred:

Traceback (most recent call last):
  File "scrapeBlitzortungLightningStrikes.py", line 67, in <module>
    main()
  File "scrapeBlitzortungLightningStrikes.py", line 30, in main
    response = requests.get("https://map.blitzortung.org/GEOjson/getjson.php?f=s&n=00", headers={"Referer": "https://map.blitzortung.org/"})
  File "/home/pi/BlitzScraper/env/lib/python3.7/site-packages/requests/api.py", line 75, in get
    return request('get', url, params=params, **kwargs)
  File "/home/pi/BlitzScraper/env/lib/python3.7/site-packages/requests/api.py", line 61, in request
    return session.request(method=method, url=url, **kwargs)
  File "/home/pi/BlitzScraper/env/lib/python3.7/site-packages/requests/sessions.py", line 542, in request
    resp = self.send(prep, **send_kwargs)
  File "/home/pi/BlitzScraper/env/lib/python3.7/site-packages/requests/sessions.py", line 655, in send
    r = adapter.send(request, **kwargs)
  File "/home/pi/BlitzScraper/env/lib/python3.7/site-packages/requests/adapters.py", line 516, in send
    raise ConnectionError(e, request=request)
requests.exceptions.ConnectionError: HTTPSConnectionPool(host='map.blitzortung.org', port=443): Max retries exceeded with url: /GEOjson/getjson.php?f=s&n=00 (Caused by NewConnectionError('<urllib3.connection.HTTPSConnection object at 0xb5e5f050>: Failed to establish a new connection: [Errno 101] Network is unreachable'))
Traceback (most recent call last):
  File "/home/pi/BlitzScraper/env/lib/python3.7/site-packages/urllib3/connection.py", line 175, in _new_conn
    (self._dns_host, self.port), self.timeout, **extra_kw
  File "/home/pi/BlitzScraper/env/lib/python3.7/site-packages/urllib3/util/connection.py", line 96, in create_connection
    raise err
  File "/home/pi/BlitzScraper/env/lib/python3.7/site-packages/urllib3/util/connection.py", line 86, in create_connection
    sock.connect(sa)
OSError: [Errno 101] Network is unreachable

During handling of the above exception, another exception occurred:

Traceback (most recent call last):
  File "/home/pi/BlitzScraper/env/lib/python3.7/site-packages/urllib3/connectionpool.py", line 706, in urlopen
    chunked=chunked,
  File "/home/pi/BlitzScraper/env/lib/python3.7/site-packages/urllib3/connectionpool.py", line 382, in _make_request
    self._validate_conn(conn)
  File "/home/pi/BlitzScraper/env/lib/python3.7/site-packages/urllib3/connectionpool.py", line 1010, in _validate_conn
    conn.connect()
  File "/home/pi/BlitzScraper/env/lib/python3.7/site-packages/urllib3/connection.py", line 358, in connect
    conn = self._new_conn()
  File "/home/pi/BlitzScraper/env/lib/python3.7/site-packages/urllib3/connection.py", line 187, in _new_conn
    self, "Failed to establish a new connection: %s" % e
urllib3.exceptions.NewConnectionError: <urllib3.connection.HTTPSConnection object at 0xb5e320b0>: Failed to establish a new connection: [Errno 101] Network is unreachable

During handling of the above exception, another exception occurred:

Traceback (most recent call last):
  File "/home/pi/BlitzScraper/env/lib/python3.7/site-packages/requests/adapters.py", line 449, in send
    timeout=timeout
  File "/home/pi/BlitzScraper/env/lib/python3.7/site-packages/urllib3/connectionpool.py", line 756, in urlopen
    method, url, error=e, _pool=self, _stacktrace=sys.exc_info()[2]
  File "/home/pi/BlitzScraper/env/lib/python3.7/site-packages/urllib3/util/retry.py", line 574, in increment
    raise MaxRetryError(_pool, url, error or ResponseError(cause))
urllib3.exceptions.MaxRetryError: HTTPSConnectionPool(host='map.blitzortung.org', port=443): Max retries exceeded with url: /GEOjson/getjson.php?f=s&n=00 (Caused by NewConnectionError('<urllib3.connection.HTTPSConnection object at 0xb5e320b0>: Failed to establish a new connection: [Errno 101] Network is unreachable'))

During handling of the above exception, another exception occurred:

Traceback (most recent call last):
  File "scrapeBlitzortungLightningStrikes.py", line 67, in <module>
    main()
  File "scrapeBlitzortungLightningStrikes.py", line 30, in main
    response = requests.get("https://map.blitzortung.org/GEOjson/getjson.php?f=s&n=00", headers={"Referer": "https://map.blitzortung.org/"})
  File "/home/pi/BlitzScraper/env/lib/python3.7/site-packages/requests/api.py", line 75, in get
    return request('get', url, params=params, **kwargs)
  File "/home/pi/BlitzScraper/env/lib/python3.7/site-packages/requests/api.py", line 61, in request
    return session.request(method=method, url=url, **kwargs)
  File "/home/pi/BlitzScraper/env/lib/python3.7/site-packages/requests/sessions.py", line 542, in request
    resp = self.send(prep, **send_kwargs)
  File "/home/pi/BlitzScraper/env/lib/python3.7/site-packages/requests/sessions.py", line 655, in send
    r = adapter.send(request, **kwargs)
  File "/home/pi/BlitzScraper/env/lib/python3.7/site-packages/requests/adapters.py", line 516, in send
    raise ConnectionError(e, request=request)
requests.exceptions.ConnectionError: HTTPSConnectionPool(host='map.blitzortung.org', port=443): Max retries exceeded with url: /GEOjson/getjson.php?f=s&n=00 (Caused by NewConnectionError('<urllib3.connection.HTTPSConnection object at 0xb5e320b0>: Failed to establish a new connection: [Errno 101] Network is unreachable'))
Traceback (most recent call last):
  File "/home/pi/BlitzScraper/env/lib/python3.7/site-packages/urllib3/connection.py", line 175, in _new_conn
    (self._dns_host, self.port), self.timeout, **extra_kw
  File "/home/pi/BlitzScraper/env/lib/python3.7/site-packages/urllib3/util/connection.py", line 96, in create_connection
    raise err
  File "/home/pi/BlitzScraper/env/lib/python3.7/site-packages/urllib3/util/connection.py", line 86, in create_connection
    sock.connect(sa)
OSError: [Errno 101] Network is unreachable

During handling of the above exception, another exception occurred:

Traceback (most recent call last):
  File "/home/pi/BlitzScraper/env/lib/python3.7/site-packages/urllib3/connectionpool.py", line 706, in urlopen
    chunked=chunked,
  File "/home/pi/BlitzScraper/env/lib/python3.7/site-packages/urllib3/connectionpool.py", line 382, in _make_request
    self._validate_conn(conn)
  File "/home/pi/BlitzScraper/env/lib/python3.7/site-packages/urllib3/connectionpool.py", line 1010, in _validate_conn
    conn.connect()
  File "/home/pi/BlitzScraper/env/lib/python3.7/site-packages/urllib3/connection.py", line 358, in connect
    conn = self._new_conn()
  File "/home/pi/BlitzScraper/env/lib/python3.7/site-packages/urllib3/connection.py", line 187, in _new_conn
    self, "Failed to establish a new connection: %s" % e
urllib3.exceptions.NewConnectionError: <urllib3.connection.HTTPSConnection object at 0xb5e780f0>: Failed to establish a new connection: [Errno 101] Network is unreachable

During handling of the above exception, another exception occurred:

Traceback (most recent call last):
  File "/home/pi/BlitzScraper/env/lib/python3.7/site-packages/requests/adapters.py", line 449, in send
    timeout=timeout
  File "/home/pi/BlitzScraper/env/lib/python3.7/site-packages/urllib3/connectionpool.py", line 756, in urlopen
    method, url, error=e, _pool=self, _stacktrace=sys.exc_info()[2]
  File "/home/pi/BlitzScraper/env/lib/python3.7/site-packages/urllib3/util/retry.py", line 574, in increment
    raise MaxRetryError(_pool, url, error or ResponseError(cause))
urllib3.exceptions.MaxRetryError: HTTPSConnectionPool(host='map.blitzortung.org', port=443): Max retries exceeded with url: /GEOjson/getjson.php?f=s&n=00 (Caused by NewConnectionError('<urllib3.connection.HTTPSConnection object at 0xb5e780f0>: Failed to establish a new connection: [Errno 101] Network is unreachable'))

During handling of the above exception, another exception occurred:

Traceback (most recent call last):
  File "scrapeBlitzortungLightningStrikes.py", line 67, in <module>
    main()
  File "scrapeBlitzortungLightningStrikes.py", line 30, in main
    response = requests.get("https://map.blitzortung.org/GEOjson/getjson.php?f=s&n=00", headers={"Referer": "https://map.blitzortung.org/"})
  File "/home/pi/BlitzScraper/env/lib/python3.7/site-packages/requests/api.py", line 75, in get
    return request('get', url, params=params, **kwargs)
  File "/home/pi/BlitzScraper/env/lib/python3.7/site-packages/requests/api.py", line 61, in request
    return session.request(method=method, url=url, **kwargs)
  File "/home/pi/BlitzScraper/env/lib/python3.7/site-packages/requests/sessions.py", line 542, in request
    resp = self.send(prep, **send_kwargs)
  File "/home/pi/BlitzScraper/env/lib/python3.7/site-packages/requests/sessions.py", line 655, in send
    r = adapter.send(request, **kwargs)
  File "/home/pi/BlitzScraper/env/lib/python3.7/site-packages/requests/adapters.py", line 516, in send
    raise ConnectionError(e, request=request)
requests.exceptions.ConnectionError: HTTPSConnectionPool(host='map.blitzortung.org', port=443): Max retries exceeded with url: /GEOjson/getjson.php?f=s&n=00 (Caused by NewConnectionError('<urllib3.connection.HTTPSConnection object at 0xb5e780f0>: Failed to establish a new connection: [Errno 101] Network is unreachable'))
Traceback (most recent call last):
  File "/home/pi/BlitzScraper/env/lib/python3.7/site-packages/urllib3/connection.py", line 175, in _new_conn
    (self._dns_host, self.port), self.timeout, **extra_kw
  File "/home/pi/BlitzScraper/env/lib/python3.7/site-packages/urllib3/util/connection.py", line 96, in create_connection
    raise err
  File "/home/pi/BlitzScraper/env/lib/python3.7/site-packages/urllib3/util/connection.py", line 86, in create_connection
    sock.connect(sa)
OSError: [Errno 101] Network is unreachable

During handling of the above exception, another exception occurred:

Traceback (most recent call last):
  File "/home/pi/BlitzScraper/env/lib/python3.7/site-packages/urllib3/connectionpool.py", line 706, in urlopen
    chunked=chunked,
  File "/home/pi/BlitzScraper/env/lib/python3.7/site-packages/urllib3/connectionpool.py", line 382, in _make_request
    self._validate_conn(conn)
  File "/home/pi/BlitzScraper/env/lib/python3.7/site-packages/urllib3/connectionpool.py", line 1010, in _validate_conn
    conn.connect()
  File "/home/pi/BlitzScraper/env/lib/python3.7/site-packages/urllib3/connection.py", line 358, in connect
    conn = self._new_conn()
  File "/home/pi/BlitzScraper/env/lib/python3.7/site-packages/urllib3/connection.py", line 187, in _new_conn
    self, "Failed to establish a new connection: %s" % e
urllib3.exceptions.NewConnectionError: <urllib3.connection.HTTPSConnection object at 0xb5ec50d0>: Failed to establish a new connection: [Errno 101] Network is unreachable

During handling of the above exception, another exception occurred:

Traceback (most recent call last):
  File "/home/pi/BlitzScraper/env/lib/python3.7/site-packages/requests/adapters.py", line 449, in send
    timeout=timeout
  File "/home/pi/BlitzScraper/env/lib/python3.7/site-packages/urllib3/connectionpool.py", line 756, in urlopen
    method, url, error=e, _pool=self, _stacktrace=sys.exc_info()[2]
  File "/home/pi/BlitzScraper/env/lib/python3.7/site-packages/urllib3/util/retry.py", line 574, in increment
    raise MaxRetryError(_pool, url, error or ResponseError(cause))
urllib3.exceptions.MaxRetryError: HTTPSConnectionPool(host='map.blitzortung.org', port=443): Max retries exceeded with url: /GEOjson/getjson.php?f=s&n=00 (Caused by NewConnectionError('<urllib3.connection.HTTPSConnection object at 0xb5ec50d0>: Failed to establish a new connection: [Errno 101] Network is unreachable'))

During handling of the above exception, another exception occurred:

Traceback (most recent call last):
  File "scrapeBlitzortungLightningStrikes.py", line 67, in <module>
    main()
  File "scrapeBlitzortungLightningStrikes.py", line 30, in main
    response = requests.get("https://map.blitzortung.org/GEOjson/getjson.php?f=s&n=00", headers={"Referer": "https://map.blitzortung.org/"})
  File "/home/pi/BlitzScraper/env/lib/python3.7/site-packages/requests/api.py", line 75, in get
    return request('get', url, params=params, **kwargs)
  File "/home/pi/BlitzScraper/env/lib/python3.7/site-packages/requests/api.py", line 61, in request
    return session.request(method=method, url=url, **kwargs)
  File "/home/pi/BlitzScraper/env/lib/python3.7/site-packages/requests/sessions.py", line 542, in request
    resp = self.send(prep, **send_kwargs)
  File "/home/pi/BlitzScraper/env/lib/python3.7/site-packages/requests/sessions.py", line 655, in send
    r = adapter.send(request, **kwargs)
  File "/home/pi/BlitzScraper/env/lib/python3.7/site-packages/requests/adapters.py", line 516, in send
    raise ConnectionError(e, request=request)
requests.exceptions.ConnectionError: HTTPSConnectionPool(host='map.blitzortung.org', port=443): Max retries exceeded with url: /GEOjson/getjson.php?f=s&n=00 (Caused by NewConnectionError('<urllib3.connection.HTTPSConnection object at 0xb5ec50d0>: Failed to establish a new connection: [Errno 101] Network is unreachable'))
[main c18c465] Update
 3 files changed, 53775 insertions(+)
 create mode 100644 data/2022-01-26.csv
To https://github.com/iancharnas/clevelandlightning.git
   5550ae5..c18c465  main -> main
[main 0d4806f] Update
 3 files changed, 43510 insertions(+)
 create mode 100644 data/2022-01-27.csv
To https://github.com/iancharnas/clevelandlightning.git
   c18c465..0d4806f  main -> main
[main 92a159d] Update
 3 files changed, 32432 insertions(+)
 create mode 100644 data/2022-01-28.csv
To https://github.com/iancharnas/clevelandlightning.git
   0d4806f..92a159d  main -> main
[main 10a967b] Update
 3 files changed, 64273 insertions(+)
 create mode 100644 data/2022-01-29.csv
To https://github.com/iancharnas/clevelandlightning.git
   92a159d..10a967b  main -> main
[main 3e85146] Update
 3 files changed, 18337 insertions(+)
 create mode 100644 data/2022-01-30.csv
To https://github.com/iancharnas/clevelandlightning.git
   10a967b..3e85146  main -> main
[main d4ca691] Update
 3 files changed, 23485 insertions(+)
 create mode 100644 data/2022-01-31.csv
To https://github.com/iancharnas/clevelandlightning.git
   3e85146..d4ca691  main -> main
[main 5ff47db] Update
 3 files changed, 105883 insertions(+)
 create mode 100644 data/2022-02-01.csv
To https://github.com/iancharnas/clevelandlightning.git
   d4ca691..5ff47db  main -> main
[main 3b2734a] Update
 3 files changed, 48769 insertions(+)
 create mode 100644 data/2022-02-02.csv
To https://github.com/iancharnas/clevelandlightning.git
   5ff47db..3b2734a  main -> main
[main 6e2e82c] Update
 3 files changed, 96292 insertions(+)
 create mode 100644 data/2022-02-03.csv
To https://github.com/iancharnas/clevelandlightning.git
   3b2734a..6e2e82c  main -> main
[main 35a739f] Update
 3 files changed, 61914 insertions(+)
 create mode 100644 data/2022-02-04.csv
To https://github.com/iancharnas/clevelandlightning.git
   6e2e82c..35a739f  main -> main
[main 485f212] Update
 3 files changed, 11079 insertions(+)
 create mode 100644 data/2022-02-05.csv
To https://github.com/iancharnas/clevelandlightning.git
   35a739f..485f212  main -> main
[main 7ff2bd0] Update
 3 files changed, 20369 insertions(+)
 create mode 100644 data/2022-02-06.csv
To https://github.com/iancharnas/clevelandlightning.git
   485f212..7ff2bd0  main -> main
[main 1dab345] Update
 3 files changed, 20278 insertions(+)
 create mode 100644 data/2022-02-07.csv
To https://github.com/iancharnas/clevelandlightning.git
   7ff2bd0..1dab345  main -> main
[main 9f374a5] Update
 3 files changed, 10874 insertions(+)
 create mode 100644 data/2022-02-08.csv
To https://github.com/iancharnas/clevelandlightning.git
   1dab345..9f374a5  main -> main
[main d62f8ef] Update
 3 files changed, 13794 insertions(+)
 create mode 100644 data/2022-02-09.csv
To https://github.com/iancharnas/clevelandlightning.git
   9f374a5..d62f8ef  main -> main
[main e3c2d89] Update
 3 files changed, 20874 insertions(+)
 create mode 100644 data/2022-02-10.csv
To https://github.com/iancharnas/clevelandlightning.git
   d62f8ef..e3c2d89  main -> main
[main 99c607b] Update
 3 files changed, 13526 insertions(+)
 create mode 100644 data/2022-02-11.csv
To https://github.com/iancharnas/clevelandlightning.git
   e3c2d89..99c607b  main -> main
[main c5053f0] Update
 3 files changed, 41859 insertions(+)
 create mode 100644 data/2022-02-12.csv
To https://github.com/iancharnas/clevelandlightning.git
   99c607b..c5053f0  main -> main
[main 782c3ad] Update
 3 files changed, 43483 insertions(+)
 create mode 100644 data/2022-02-13.csv
To https://github.com/iancharnas/clevelandlightning.git
   c5053f0..782c3ad  main -> main
[main 2769c84] Update
 3 files changed, 20770 insertions(+)
 create mode 100644 data/2022-02-14.csv
To https://github.com/iancharnas/clevelandlightning.git
   782c3ad..2769c84  main -> main
[main 9d909fe] Update
 3 files changed, 27144 insertions(+)
 create mode 100644 data/2022-02-15.csv
To https://github.com/iancharnas/clevelandlightning.git
   2769c84..9d909fe  main -> main
[main 2ea6c7f] Update
 3 files changed, 39196 insertions(+)
 create mode 100644 data/2022-02-16.csv
To https://github.com/iancharnas/clevelandlightning.git
   9d909fe..2ea6c7f  main -> main
[main 0165427] Update
 4 files changed, 97637 insertions(+), 1 deletion(-)
 create mode 100644 data/2022-02-17.csv
To https://github.com/iancharnas/clevelandlightning.git
   2ea6c7f..0165427  main -> main
[main 32667bf] Update
 3 files changed, 32737 insertions(+)
 create mode 100644 data/2022-02-18.csv
To https://github.com/iancharnas/clevelandlightning.git
   0165427..32667bf  main -> main
[main 95dfe1f] Update
 3 files changed, 27170 insertions(+)
 create mode 100644 data/2022-02-19.csv
To https://github.com/iancharnas/clevelandlightning.git
   32667bf..95dfe1f  main -> main
[main 24233b7] Update
 3 files changed, 36180 insertions(+)
 create mode 100644 data/2022-02-20.csv
To https://github.com/iancharnas/clevelandlightning.git
   95dfe1f..24233b7  main -> main
[main 830e817] Update
 3 files changed, 68991 insertions(+)
 create mode 100644 data/2022-02-21.csv
To https://github.com/iancharnas/clevelandlightning.git
   24233b7..830e817  main -> main
[main c4b66fc] Update
 4 files changed, 148347 insertions(+), 1 deletion(-)
 create mode 100644 data/2022-02-22.csv
To https://github.com/iancharnas/clevelandlightning.git
   830e817..c4b66fc  main -> main
[main dccd530] Update
 3 files changed, 58891 insertions(+)
 create mode 100644 data/2022-02-23.csv
To https://github.com/iancharnas/clevelandlightning.git
   c4b66fc..dccd530  main -> main
[main 44c4880] Update
 3 files changed, 64631 insertions(+)
 create mode 100644 data/2022-02-24.csv
To https://github.com/iancharnas/clevelandlightning.git
   dccd530..44c4880  main -> main
[main fed82ea] Update
 3 files changed, 31306 insertions(+)
 create mode 100644 data/2022-02-25.csv
To https://github.com/iancharnas/clevelandlightning.git
   44c4880..fed82ea  main -> main
[main 3cbb302] Update
 3 files changed, 31246 insertions(+)
 create mode 100644 data/2022-02-26.csv
To https://github.com/iancharnas/clevelandlightning.git
   fed82ea..3cbb302  main -> main
[main c9368bf] Update
 3 files changed, 15099 insertions(+)
 create mode 100644 data/2022-02-27.csv
To https://github.com/iancharnas/clevelandlightning.git
   3cbb302..c9368bf  main -> main
[main 20801f4] Update
 3 files changed, 26608 insertions(+)
 create mode 100644 data/2022-02-28.csv
To https://github.com/iancharnas/clevelandlightning.git
   c9368bf..20801f4  main -> main
[main 5e275e6] Update
 3 files changed, 58246 insertions(+)
 create mode 100644 data/2022-03-01.csv
To https://github.com/iancharnas/clevelandlightning.git
   20801f4..5e275e6  main -> main
[main 9aae853] Update
 3 files changed, 35422 insertions(+)
 create mode 100644 data/2022-03-02.csv
To https://github.com/iancharnas/clevelandlightning.git
   5e275e6..9aae853  main -> main
[main 089d238] Update
 3 files changed, 36594 insertions(+)
 create mode 100644 data/2022-03-03.csv
To https://github.com/iancharnas/clevelandlightning.git
   9aae853..089d238  main -> main
[main 824f4ca] Update
 3 files changed, 24692 insertions(+)
 create mode 100644 data/2022-03-04.csv
To https://github.com/iancharnas/clevelandlightning.git
   089d238..824f4ca  main -> main
[main 10060b1] Update
 3 files changed, 71810 insertions(+)
 create mode 100644 data/2022-03-05.csv
To https://github.com/iancharnas/clevelandlightning.git
   824f4ca..10060b1  main -> main
[main b97ae50] Update
 4 files changed, 119159 insertions(+), 1 deletion(-)
 rewrite clevelandstrikes.json (66%)
 create mode 100644 data/2022-03-06.csv
To https://github.com/iancharnas/clevelandlightning.git
   10060b1..b97ae50  main -> main
[main c2f8b96] Update
 4 files changed, 111670 insertions(+), 1 deletion(-)
 rewrite clevelandstrikes.json (80%)
 create mode 100644 data/2022-03-07.csv
To https://github.com/iancharnas/clevelandlightning.git
   b97ae50..c2f8b96  main -> main
[main 2d0f0cf] Update
 3 files changed, 99088 insertions(+)
 create mode 100644 data/2022-03-08.csv
To https://github.com/iancharnas/clevelandlightning.git
   c2f8b96..2d0f0cf  main -> main
[main 60a8d2f] Update
 3 files changed, 199010 insertions(+)
 create mode 100644 data/2022-03-09.csv
To https://github.com/iancharnas/clevelandlightning.git
   2d0f0cf..60a8d2f  main -> main
[main 1de3abb] Update
 3 files changed, 99485 insertions(+)
 create mode 100644 data/2022-03-10.csv
To https://github.com/iancharnas/clevelandlightning.git
   60a8d2f..1de3abb  main -> main
[main f3c95ae] Update
 3 files changed, 121264 insertions(+)
 create mode 100644 data/2022-03-11.csv
To https://github.com/iancharnas/clevelandlightning.git
   1de3abb..f3c95ae  main -> main
[main 2061ba6] Update
 3 files changed, 159280 insertions(+)
 create mode 100644 data/2022-03-12.csv
To https://github.com/iancharnas/clevelandlightning.git
   f3c95ae..2061ba6  main -> main
[main 72a2704] Update
 3 files changed, 34579 insertions(+)
 create mode 100644 data/2022-03-13.csv
To https://github.com/iancharnas/clevelandlightning.git
   2061ba6..72a2704  main -> main
[main da77395] Update
 3 files changed, 33714 insertions(+)
 create mode 100644 data/2022-03-14.csv
To https://github.com/iancharnas/clevelandlightning.git
   72a2704..da77395  main -> main
[main 7586c09] Update
 3 files changed, 178983 insertions(+)
 create mode 100644 data/2022-03-15.csv
To https://github.com/iancharnas/clevelandlightning.git
   da77395..7586c09  main -> main
[main 0dbc954] Update
 3 files changed, 111202 insertions(+)
 create mode 100644 data/2022-03-16.csv
To https://github.com/iancharnas/clevelandlightning.git
   7586c09..0dbc954  main -> main
[main 3dd661a] Update
 3 files changed, 132788 insertions(+)
 create mode 100644 data/2022-03-17.csv
To https://github.com/iancharnas/clevelandlightning.git
   0dbc954..3dd661a  main -> main
[main 9902d98] Update
 4 files changed, 277503 insertions(+), 1 deletion(-)
 rewrite clevelandstrikes.json (78%)
 create mode 100644 data/2022-03-18.csv
To https://github.com/iancharnas/clevelandlightning.git
   3dd661a..9902d98  main -> main
[main 4923f47] Update
 4 files changed, 118310 insertions(+), 1 deletion(-)
 rewrite clevelandstrikes.json (77%)
 create mode 100644 data/2022-03-19.csv
To https://github.com/iancharnas/clevelandlightning.git
   9902d98..4923f47  main -> main
[main e75d09f] Update
 2 files changed, 6 insertions(+)
 create mode 100644 data/2022-03-20.csv
To https://github.com/iancharnas/clevelandlightning.git
   4923f47..e75d09f  main -> main
[main 5835300] Update
 2 files changed, 5 insertions(+)
 create mode 100644 data/2022-03-21.csv
To https://github.com/iancharnas/clevelandlightning.git
   e75d09f..5835300  main -> main
[main 0d15139] Update
 2 files changed, 5 insertions(+)
 create mode 100644 data/2022-03-22.csv
To https://github.com/iancharnas/clevelandlightning.git
   5835300..0d15139  main -> main
[main 974a011] Update
 3 files changed, 36244 insertions(+), 1 deletion(-)
 create mode 100644 data/2022-03-23.csv
To https://github.com/iancharnas/clevelandlightning.git
   0d15139..974a011  main -> main
[main f05b07f] Update
 4 files changed, 129968 insertions(+), 1 deletion(-)
 rewrite clevelandstrikes.json (77%)
 create mode 100644 data/2022-03-24.csv
To https://github.com/iancharnas/clevelandlightning.git
   974a011..f05b07f  main -> main
[main 288c875] Update
 3 files changed, 40732 insertions(+)
 create mode 100644 data/2022-03-25.csv
To https://github.com/iancharnas/clevelandlightning.git
   f05b07f..288c875  main -> main
[main 7962bc6] Update
 3 files changed, 26485 insertions(+)
 create mode 100644 data/2022-03-26.csv
To https://github.com/iancharnas/clevelandlightning.git
   288c875..7962bc6  main -> main
[main 7594460] Update
 3 files changed, 11871 insertions(+)
 create mode 100644 data/2022-03-27.csv
To https://github.com/iancharnas/clevelandlightning.git
   7962bc6..7594460  main -> main
[main c76cf5a] Update
 3 files changed, 7981 insertions(+)
 create mode 100644 data/2022-03-28.csv
To https://github.com/iancharnas/clevelandlightning.git
   7594460..c76cf5a  main -> main
[main f1730ed] Update
 3 files changed, 38084 insertions(+)
 create mode 100644 data/2022-03-29.csv
To https://github.com/iancharnas/clevelandlightning.git
   c76cf5a..f1730ed  main -> main
[main b4b15c9] Update
 4 files changed, 155846 insertions(+), 1 deletion(-)
 rewrite clevelandstrikes.json (77%)
 create mode 100644 data/2022-03-30.csv
To https://github.com/iancharnas/clevelandlightning.git
   f1730ed..b4b15c9  main -> main
[main f422834] Update
 4 files changed, 217191 insertions(+), 1 deletion(-)
 rewrite clevelandstrikes.json (77%)
 create mode 100644 data/2022-03-31.csv
To https://github.com/iancharnas/clevelandlightning.git
   b4b15c9..f422834  main -> main
[main 259291c] Update
 3 files changed, 261544 insertions(+)
 create mode 100644 data/2022-04-01.csv
To https://github.com/iancharnas/clevelandlightning.git
   f422834..259291c  main -> main
[main 849a70d] Update
 3 files changed, 314897 insertions(+)
 create mode 100644 data/2022-04-02.csv
To https://github.com/iancharnas/clevelandlightning.git
   259291c..849a70d  main -> main
[main 29ac597] Update
 3 files changed, 133102 insertions(+)
 create mode 100644 data/2022-04-03.csv
To https://github.com/iancharnas/clevelandlightning.git
   849a70d..29ac597  main -> main
[main 29beece] Update
 3 files changed, 83863 insertions(+)
 create mode 100644 data/2022-04-04.csv
To https://github.com/iancharnas/clevelandlightning.git
   29ac597..29beece  main -> main
[main b10eaf2] Update
 3 files changed, 259752 insertions(+)
 create mode 100644 data/2022-04-05.csv
To https://github.com/iancharnas/clevelandlightning.git
   29beece..b10eaf2  main -> main
[main 63140d4] Update
 3 files changed, 264976 insertions(+)
 create mode 100644 data/2022-04-06.csv
To https://github.com/iancharnas/clevelandlightning.git
   b10eaf2..63140d4  main -> main
[main 6231cb8] Update
 4 files changed, 416026 insertions(+), 1 deletion(-)
 create mode 100644 data/2022-04-07.csv
To https://github.com/iancharnas/clevelandlightning.git
   63140d4..6231cb8  main -> main
[main ae98ab9] Update
 4 files changed, 186108 insertions(+), 1 deletion(-)
 create mode 100644 data/2022-04-08.csv
To https://github.com/iancharnas/clevelandlightning.git
   6231cb8..ae98ab9  main -> main
[main b796817] Update
 4 files changed, 86735 insertions(+), 1 deletion(-)
 create mode 100644 data/2022-04-09.csv
To https://github.com/iancharnas/clevelandlightning.git
   ae98ab9..b796817  main -> main
[main 7b4972a] Update
 3 files changed, 38181 insertions(+)
 create mode 100644 data/2022-04-10.csv
To https://github.com/iancharnas/clevelandlightning.git
   b796817..7b4972a  main -> main
[main 6739346] Update
 4 files changed, 135004 insertions(+), 1 deletion(-)
 rewrite clevelandstrikes.json (64%)
 create mode 100644 data/2022-04-11.csv
To https://github.com/iancharnas/clevelandlightning.git
   7b4972a..6739346  main -> main
[main b90b367] Update
 3 files changed, 154601 insertions(+)
 create mode 100644 data/2022-04-12.csv
To https://github.com/iancharnas/clevelandlightning.git
   6739346..b90b367  main -> main
[main bfe0541] Update
 4 files changed, 304220 insertions(+), 1 deletion(-)
 create mode 100644 data/2022-04-13.csv
To https://github.com/iancharnas/clevelandlightning.git
   b90b367..bfe0541  main -> main
[main 559fd1f] Update
 3 files changed, 172885 insertions(+)
 create mode 100644 data/2022-04-14.csv
To https://github.com/iancharnas/clevelandlightning.git
   bfe0541..559fd1f  main -> main
[main 060973b] Update
 3 files changed, 258868 insertions(+)
 create mode 100644 data/2022-04-15.csv
To https://github.com/iancharnas/clevelandlightning.git
   559fd1f..060973b  main -> main
[main d163e58] Update
 3 files changed, 214932 insertions(+)
 create mode 100644 data/2022-04-16.csv
To https://github.com/iancharnas/clevelandlightning.git
   060973b..d163e58  main -> main
[main d1bbad4] Update
 3 files changed, 263990 insertions(+)
 create mode 100644 data/2022-04-17.csv
To https://github.com/iancharnas/clevelandlightning.git
   d163e58..d1bbad4  main -> main
[main 0be00c2] Update
 3 files changed, 218238 insertions(+)
 create mode 100644 data/2022-04-18.csv
To https://github.com/iancharnas/clevelandlightning.git
   d1bbad4..0be00c2  main -> main
[main 6298ca1] Update
 4 files changed, 85250 insertions(+), 1 deletion(-)
 create mode 100644 data/2022-04-19.csv
To https://github.com/iancharnas/clevelandlightning.git
   0be00c2..6298ca1  main -> main
Traceback (most recent call last):
  File "/home/pi/BlitzScraper/env/lib/python3.7/site-packages/urllib3/connectionpool.py", line 706, in urlopen
    chunked=chunked,
  File "/home/pi/BlitzScraper/env/lib/python3.7/site-packages/urllib3/connectionpool.py", line 445, in _make_request
    six.raise_from(e, None)
  File "<string>", line 3, in raise_from
  File "/home/pi/BlitzScraper/env/lib/python3.7/site-packages/urllib3/connectionpool.py", line 440, in _make_request
    httplib_response = conn.getresponse()
  File "/usr/lib/python3.7/http/client.py", line 1352, in getresponse
    response.begin()
  File "/usr/lib/python3.7/http/client.py", line 310, in begin
    version, status, reason = self._read_status()
  File "/usr/lib/python3.7/http/client.py", line 279, in _read_status
    raise RemoteDisconnected("Remote end closed connection without"
http.client.RemoteDisconnected: Remote end closed connection without response

During handling of the above exception, another exception occurred:

Traceback (most recent call last):
  File "/home/pi/BlitzScraper/env/lib/python3.7/site-packages/requests/adapters.py", line 449, in send
    timeout=timeout
  File "/home/pi/BlitzScraper/env/lib/python3.7/site-packages/urllib3/connectionpool.py", line 756, in urlopen
    method, url, error=e, _pool=self, _stacktrace=sys.exc_info()[2]
  File "/home/pi/BlitzScraper/env/lib/python3.7/site-packages/urllib3/util/retry.py", line 532, in increment
    raise six.reraise(type(error), error, _stacktrace)
  File "/home/pi/BlitzScraper/env/lib/python3.7/site-packages/urllib3/packages/six.py", line 769, in reraise
    raise value.with_traceback(tb)
  File "/home/pi/BlitzScraper/env/lib/python3.7/site-packages/urllib3/connectionpool.py", line 706, in urlopen
    chunked=chunked,
  File "/home/pi/BlitzScraper/env/lib/python3.7/site-packages/urllib3/connectionpool.py", line 445, in _make_request
    six.raise_from(e, None)
  File "<string>", line 3, in raise_from
  File "/home/pi/BlitzScraper/env/lib/python3.7/site-packages/urllib3/connectionpool.py", line 440, in _make_request
    httplib_response = conn.getresponse()
  File "/usr/lib/python3.7/http/client.py", line 1352, in getresponse
    response.begin()
  File "/usr/lib/python3.7/http/client.py", line 310, in begin
    version, status, reason = self._read_status()
  File "/usr/lib/python3.7/http/client.py", line 279, in _read_status
    raise RemoteDisconnected("Remote end closed connection without"
urllib3.exceptions.ProtocolError: ('Connection aborted.', RemoteDisconnected('Remote end closed connection without response'))

During handling of the above exception, another exception occurred:

Traceback (most recent call last):
  File "scrapeBlitzortungLightningStrikes.py", line 67, in <module>
    main()
  File "scrapeBlitzortungLightningStrikes.py", line 30, in main
    response = requests.get("https://map.blitzortung.org/GEOjson/getjson.php?f=s&n=00", headers={"Referer": "https://map.blitzortung.org/"})
  File "/home/pi/BlitzScraper/env/lib/python3.7/site-packages/requests/api.py", line 75, in get
    return request('get', url, params=params, **kwargs)
  File "/home/pi/BlitzScraper/env/lib/python3.7/site-packages/requests/api.py", line 61, in request
    return session.request(method=method, url=url, **kwargs)
  File "/home/pi/BlitzScraper/env/lib/python3.7/site-packages/requests/sessions.py", line 542, in request
    resp = self.send(prep, **send_kwargs)
  File "/home/pi/BlitzScraper/env/lib/python3.7/site-packages/requests/sessions.py", line 655, in send
    r = adapter.send(request, **kwargs)
  File "/home/pi/BlitzScraper/env/lib/python3.7/site-packages/requests/adapters.py", line 498, in send
    raise ConnectionError(err, request=request)
requests.exceptions.ConnectionError: ('Connection aborted.', RemoteDisconnected('Remote end closed connection without response'))
[main 24f91db] Update
 3 files changed, 99112 insertions(+)
 create mode 100644 data/2022-04-20.csv
To https://github.com/iancharnas/clevelandlightning.git
   6298ca1..24f91db  main -> main
[main b962f89] Update
 3 files changed, 59035 insertions(+)
 create mode 100644 data/2022-04-21.csv
To https://github.com/iancharnas/clevelandlightning.git
   24f91db..b962f89  main -> main
[main de436f1] Update
 3 files changed, 216777 insertions(+)
 create mode 100644 data/2022-04-22.csv
To https://github.com/iancharnas/clevelandlightning.git
   b962f89..de436f1  main -> main
[main 11d4c79] Update
 3 files changed, 247903 insertions(+)
 create mode 100644 data/2022-04-23.csv
To https://github.com/iancharnas/clevelandlightning.git
   de436f1..11d4c79  main -> main
[main b37a1bc] Update
 3 files changed, 229054 insertions(+)
 create mode 100644 data/2022-04-24.csv
To https://github.com/iancharnas/clevelandlightning.git
   11d4c79..b37a1bc  main -> main
[main 5ea722c] Update
 4 files changed, 236461 insertions(+), 1 deletion(-)
 rewrite clevelandstrikes.json (73%)
 create mode 100644 data/2022-04-25.csv
To https://github.com/iancharnas/clevelandlightning.git
   b37a1bc..5ea722c  main -> main
[main db12c16] Update
 4 files changed, 189587 insertions(+), 1 deletion(-)
 rewrite clevelandstrikes.json (71%)
 create mode 100644 data/2022-04-26.csv
To https://github.com/iancharnas/clevelandlightning.git
   5ea722c..db12c16  main -> main
[main a0cf71c] Update
 3 files changed, 122407 insertions(+)
 create mode 100644 data/2022-04-27.csv
To https://github.com/iancharnas/clevelandlightning.git
   db12c16..a0cf71c  main -> main
[main 0c90c1f] Update
 3 files changed, 116881 insertions(+)
 create mode 100644 data/2022-04-28.csv
To https://github.com/iancharnas/clevelandlightning.git
   a0cf71c..0c90c1f  main -> main
[main 9ff90e6] Update
 3 files changed, 192786 insertions(+)
 create mode 100644 data/2022-04-29.csv
To https://github.com/iancharnas/clevelandlightning.git
   0c90c1f..9ff90e6  main -> main
